LINE 282 : 2018-01-25 01:25:14,600 [INFO    ] Parsing data files for GSEA.............................
LINE 82  : 2018-01-25 01:25:15,317 [INFO    ] User Defined gene sets is given.......continue..........
LINE 139 : 2018-01-25 01:25:15,357 [INFO    ] 0000 gene_sets have been filtered out when max_size=1000 and min_size=2
LINE 296 : 2018-01-25 01:25:15,357 [INFO    ] 0001 gene_sets used for further statistical testing.....
LINE 297 : 2018-01-25 01:25:15,357 [INFO    ] Start to run GSEA...Might take a while..................
LINE 340 : 2018-01-25 01:25:15,596 [DEBUG   ] Start to compute enrichment socres......................
LINE 352 : 2018-01-25 01:25:15,599 [DEBUG   ] Start to compute esnulls...............................
LINE 530 : 2018-01-25 01:25:16,617 [DEBUG   ] Start to compute pvals..................................
LINE 552 : 2018-01-25 01:25:16,618 [DEBUG   ] Compute normalized enrichment score and normalized esnull
LINE 568 : 2018-01-25 01:25:16,618 [DEBUG   ] start to compute fdrs..................................
LINE 602 : 2018-01-25 01:25:16,619 [DEBUG   ] Statistial testing finished.............................
LINE 309 : 2018-01-25 01:25:16,620 [INFO    ] Start to generate gseapy reports, and produce figures...
LINE 321 : 2018-01-25 01:25:20,638 [INFO    ] Congratulations. GSEApy run successfully................
LINE 135 : 2018-01-25 01:25:27,235 [ERROR   ] Internal Server Error: /calculation/
Traceback (most recent call last):
  File "/home/ubuntu/.local/lib/python2.7/site-packages/django/core/handlers/exception.py", line 41, in inner
    response = get_response(request)
  File "/home/ubuntu/.local/lib/python2.7/site-packages/django/core/handlers/base.py", line 187, in _get_response
    response = self.process_exception_by_middleware(e, request)
  File "/home/ubuntu/.local/lib/python2.7/site-packages/django/core/handlers/base.py", line 185, in _get_response
    response = wrapped_callback(request, *callback_args, **callback_kwargs)
  File "/home/ubuntu/django_proj/pcta_updated/main/views.py", line 283, in call_calculation
    file_list, table_list = set_calculator(input_data, group_info, group_samples, request.session.session_key)
  File "/home/ubuntu/django_proj/pcta_updated/main/views.py", line 883, in set_calculator
    selected_network_expr = df_all[group_samples[0]].loc[network_data.index.tolist()[:10]]
  File "/home/ubuntu/.local/lib/python2.7/site-packages/pandas/core/indexing.py", line 1328, in __getitem__
    return self._getitem_axis(key, axis=0)
  File "/home/ubuntu/.local/lib/python2.7/site-packages/pandas/core/indexing.py", line 1541, in _getitem_axis
    return self._getitem_iterable(key, axis=axis)
  File "/home/ubuntu/.local/lib/python2.7/site-packages/pandas/core/indexing.py", line 1081, in _getitem_iterable
    self._has_valid_type(key, axis)
  File "/home/ubuntu/.local/lib/python2.7/site-packages/pandas/core/indexing.py", line 1418, in _has_valid_type
    (key, self.obj._get_axis_name(axis)))
KeyError: "None of [['BRCA1', 'THRA', 'ZBTB18', 'RXRG', 'THRB', 'EED', 'RARA', 'CEBPE', 'PHC1', 'NKX2-1']] are in the [index]"
